Workbook

Sheet Control
B1: AXIONIA — Three-Statement Operating Model
B2: $1M raised now funds a disciplined build to a Year-3 milestone. Flip the scenario toggle — every statement recalculates.
B4: TOGGLE
B5: Scenario | C5: Base
B8: active index | C8: =MATCH(C5,Scenarios!$B$25:$B$27,0) -> 2
B10: WHAT EACH SCENARIO MEANS
B11: Bear | C11: Year-3 milestone comes in soft — no third-party data buyer yet. No further raise taken; compounds from cash flow. Profitable, independent, ~$11.8M by Year 7.
B12: Base | C12: Milestone clears — a third party pays for the benchmark data. A right-sized ~$8M Series A funds accelerated deployment. ~$60.6M by Year 7.
B13: Bull | C13: OPTION, not a plan. If execution goes well, Years 5-6 arrive with ~$23M revenue, ~$17M cash and positive operating cash flow — a position with real strategic optionality. Bull models what a new product line or market (likely acquisition-shaped) could add if one presents itself. The ~$30M Series B is illustrative of that shape, sized to the opportunity, not a committed raise. ~$91.3M by Year 7.
B16: AT A GLANCE · active scenario
C17: Year 1 | D17: Year 2 | E17: Year 3 | F17: Year 4 | G17: Year 5 | H17: Year 6 | I17: Year 7
B18: Revenue | C18: ='P&L'!C5 -> 348750 | D18: ='P&L'!D5 -> 1342125 | E18: ='P&L'!E5 -> 3177500 | F18: ='P&L'!F5 -> 10188875 | G18: ='P&L'!G5 -> 23192222 | H18: ='P&L'!H5 -> 40601094 | I18: ='P&L'!I5 -> 60581809
B19: EBIT | C19: ='P&L'!C17 -> -130983.33 | D19: ='P&L'!D17 -> 58491.667 | E19: ='P&L'!E17 -> 834479.17 | F19: ='P&L'!F17 -> 1377743.1 | G19: ='P&L'!G17 -> 7458229.5 | H19: ='P&L'!H17 -> 18995783 | I19: ='P&L'!I17 -> 33405333
B20: Net income | C20: ='P&L'!C25 -> -130983.33 | D20: ='P&L'!D25 -> 94360.817 | E20: ='P&L'!E25 -> 657962.72 | F20: ='P&L'!F25 -> 1070914.1 | G20: ='P&L'!G25 -> 5849234.4 | H20: ='P&L'!H25 -> 14566565 | I20: ='P&L'!I25 -> 25660495
B21: Ending cash | C21: ='Balance Sheet'!C6 -> 896728.77 | D21: ='Balance Sheet'!D6 -> 1044806.8 | E21: ='Balance Sheet'!E6 -> 1735952.9 | F21: ='Balance Sheet'!F6 -> 11153532 | G21: ='Balance Sheet'!G6 -> 17219101 | H21: ='Balance Sheet'!H6 -> 31775278 | I21: ='Balance Sheet'!I6 -> 57312407
B22: Balance sheet check | C22: ='Balance Sheet'!C20 -> 0 | D22: ='Balance Sheet'!D20 -> 0 | E22: ='Balance Sheet'!E20 -> 0 | F22: ='Balance Sheet'!F20 -> 0 | G22: ='Balance Sheet'!G20 -> 0 | H22: ='Balance Sheet'!H20 -> 0 | I22: ='Balance Sheet'!I20 -> 0
B25: HOW THIS WORKBOOK IS ORGANIZED
B26: NAVIGATE | C26: Control · Summary | F26: Set the scenario toggle here; Summary gives the one-page picture.
B27: THE ASK | C27: Use of Funds · Valuation · Cap Table · Exit & Return | F27: Why we're raising, how it's priced, who owns what, what everyone makes.
B28: THE STATEMENTS | C28: P&L · Cash Flow · Balance Sheet | F28: Standard three-statement output. Balance sheet check row must read zero.
B29: THE DRIVERS | C29: Scenarios · Revenue Build · Staffing Plan | F29: Where revenue and headcount actually come from. Revenue is built bottom-up, not asserted.
B30: BACKUP | C30: S&M · Product & Data Eng · G&A & Exec Comp · COGS · WC & Capex | F30: Line-by-line cost build-ups. Every blue cell is an input you can change.
B32: Blue cells are inputs. Green cells pull from another tab. Everything else is calculated — changing a blue cell flows through the entire model.

Sheet Summary
B1: AXIONIA — Operating Model Summary
B2: A $1M raise funds the build to a Year-3 milestone, which sets the funding path forward. Set the toggle on the Control tab — this page follows.
C4: Year 1 | D4: Year 2 | E4: Year 3 | F4: Year 4 | G4: Year 5 | H4: Year 6 | I4: Year 7
B5: Revenue | C5: ='P&L'!C5 -> 348750 | D5: ='P&L'!D5 -> 1342125 | E5: ='P&L'!E5 -> 3177500 | F5: ='P&L'!F5 -> 10188875 | G5: ='P&L'!G5 -> 23192222 | H5: ='P&L'!H5 -> 40601094 | I5: ='P&L'!I5 -> 60581809
B6: Gross margin | C6: ='P&L'!C8 -> 0.9655914 | D6: ='P&L'!D8 -> 0.88555462 | E6: ='P&L'!E8 -> 0.69542093 | F6: ='P&L'!F8 -> 0.79209677 | G6: ='P&L'!G8 -> 0.83717817 | H6: ='P&L'!H8 -> 0.87240738 | I6: ='P&L'!I8 -> 0.89131061
B7: EBIT | C7: ='P&L'!C17 -> -130983.33 | D7: ='P&L'!D17 -> 58491.667 | E7: ='P&L'!E17 -> 834479.17 | F7: ='P&L'!F17 -> 1377743.1 | G7: ='P&L'!G17 -> 7458229.5 | H7: ='P&L'!H17 -> 18995783 | I7: ='P&L'!I17 -> 33405333
B8: Net income | C8: ='P&L'!C25 -> -130983.33 | D8: ='P&L'!D25 -> 94360.817 | E8: ='P&L'!E25 -> 657962.72 | F8: ='P&L'!F25 -> 1070914.1 | G8: ='P&L'!G25 -> 5849234.4 | H8: ='P&L'!H25 -> 14566565 | I8: ='P&L'!I25 -> 25660495
B9: Cash from operations | C9: ='Cash Flow'!C11 -> -93271.233 | D9: ='Cash Flow'!D11 -> 151078.05 | E9: ='Cash Flow'!E11 -> 738808.55 | F9: ='Cash Flow'!F11 -> 1570412.1 | G9: ='Cash Flow'!G11 -> 6413452.7 | H9: ='Cash Flow'!H11 -> 15165193 | I9: ='Cash Flow'!I11 -> 26445857
B10: Ending cash | C10: ='Cash Flow'!C23 -> 896728.77 | D10: ='Cash Flow'!D23 -> 1044806.8 | E10: ='Cash Flow'!E23 -> 1735952.9 | F10: ='Cash Flow'!F23 -> 11153532 | G10: ='Cash Flow'!G23 -> 17219101 | H10: ='Cash Flow'!H23 -> 31775278 | I10: ='Cash Flow'!I23 -> 57312407
B11: Capital raised (cumulative) | C11: ='Balance Sheet'!C17 -> 1000000 | D11: ='Balance Sheet'!D17 -> 1000000 | E11: ='Balance Sheet'!E17 -> 1000000 | F11: ='Balance Sheet'!F17 -> 9000000 | G11: ='Balance Sheet'!G17 -> 9000000 | H11: ='Balance Sheet'!H17 -> 9000000 | I11: ='Balance Sheet'!I17 -> 9000000
B13: BEAR / BASE / BULL AT YEAR 7
C14: Bear | D14: Base | E14: Bull
B15: Year 7 revenue | C15: =INDEX(Scenarios!$C$6:$I$8,1,7) -> 11816789 | D15: =INDEX(Scenarios!$C$6:$I$8,2,7) -> 60581809 | E15: =INDEX(Scenarios!$C$6:$I$8,3,7) -> 91343109
B16: Founder ownership | C16: ='Cap Table'!C18 -> 0.85714286 | D16: ='Cap Table'!C19 -> 0.67181467 | E16: ='Cap Table'!C20 -> 0.503861
B17: Capital raised, total | C17: =SUM(INDEX(Scenarios!$C$21:$I$23,1,1):INDEX(Scenarios!$C$21:$I$23,1,7)) -> 1000000 | D17: =SUM(INDEX(Scenarios!$C$21:$I$23,2,1):INDEX(Scenarios!$C$21:$I$23,2,7)) -> 9000000 | E17: =SUM(INDEX(Scenarios!$C$21:$I$23,3,1):INDEX(Scenarios!$C$21:$I$23,3,7)) -> 39000000
B19: WHAT THE MODEL SAYS
B20: All three scenarios share the identical Year 1-3 build, funded by the $1M raised now. The Year-3 milestone determines the funding path forward.
B21: Gate test: has a third party (health plan, PE diligence, reinsurer) paid for the benchmark/ratings data?
B22: Bear (gate soft): no further raise; compounds to ~$11.8M revenue, ~$5.7M EBIT, ~73% founder ownership by Year 7 (post pool & partner).
B23: Base (gate clears): a right-sized ~$8M Series A, fully deployed; ~$60.6M revenue, ~$31.6M EBIT, ~57% founder ownership by Year 7.
B24: Bull (upside option, not a plan): if a new product line or market opportunity presents itself at Year 5-6, an illustrative ~$30M Series B funds it; ~$91.3M revenue, ~43% founder ownership by Year 7. The point is that strong execution creates options — not that this specific path is committed.
B25: The balance sheet balances in every year of every scenario — see the check row on the Balance Sheet tab.
B26: Policy choices flagged for discussion: product/data-eng spend expensed as incurred (not capitalized); NOL tax carryforward
B27: at a 26% post-NOL rate, simplified to ignore the TCJA 80%-of-taxable-income usage limit.

Sheet Use of Funds
B1: Use of Funds — the $8M Series A
B2: What the capital buys, why cash still accumulates, and what to do about it. Base vs. Bear is the cleanest way to isolate what the money actually funds.
B4: THE CORE POINT
B5: Right-sized and deployed. The original $15M left capital permanently undrawn, because the business turns cash-positive in Year 2 and funds most of its own growth. The round is now $8M — sized to the actual pre-revenue investment window — and paired with accelerated hiring and data investment so the capital is consumed, not parked.
B7: INCREMENTAL INVESTMENT · Base over Bear, Years 4-7
C8: Year 4 | D8: Year 5 | E8: Year 6 | F8: Year 7 | G8: 4-yr total
B9: Sales & marketing (reps, channel, programs) | C9: 2555000 | D9: 4755000 | E9: 6365000 | F9: 8080000 | G9: =SUM(C9:F9) -> 21755000
B10: Product, data engineering & authority | C10: 1890000 | D10: 3845000 | E10: 5350000 | F10: 6730000 | G10: =SUM(C10:F10) -> 17815000
B11: G&A (incl. CFO hire, expanded ops) | C11: 220000 | D11: 720000 | E11: 1025000 | F11: 1320000 | G11: =SUM(C11:F11) -> 3285000
B12: Total incremental investment | C12: =SUM(C9:C11) -> 4665000 | D12: =SUM(D9:D11) -> 9320000 | E12: =SUM(E9:E11) -> 12740000 | F12: =SUM(F9:F11) -> 16130000 | G12: =SUM(G9:G11) -> 42855000
B13: Series A raised | G13: ='Cap Table'!$D$7 -> 8000000
B14: Funded by operating cash flow | G14: =G12-G13 -> 34855000
B15: =" the raise covers ~"&TEXT(G13/G12,"0%")&" of the incremental build; the business funds the rest as revenue scales" -> the raise covers ~19% of the incremental build; the business funds the rest as revenue scales
B18: WHAT THE CAPITAL BUYS · Bear vs. Base at Year 7
C19: Bear | D19: Base | E19: Delta
B20: Year 7 revenue | C20: =INDEX(Scenarios!$C$6:$I$8,1,7) -> 11816789 | D20: =INDEX(Scenarios!$C$6:$I$8,2,7) -> 60581809 | E20: =D20-C20 -> 48765020
B21: Year 7 headcount | C21: 15 | D21: 62 | E21: =D21-C21 -> 47
B22: Revenue per $1 of Series A capital | E22: =E20/G13 -> 6.0956275
B23: The $8M does not plug a funding gap — it buys permission to hire ahead of revenue and deepen the benchmark data asset years before either pays back. Bear proves the business works without capital ($11.8M). Base uses capital to compress the timeline ($60.6M) — on a smaller round than originally modeled.
B25: DECISION · right-size the round, then deploy it
B26: Shrinking the raise alone would not have solved the idle-cash problem — at any raise size, the business still generates enough operating cash flow to accumulate a large balance by Year 7. The fix required both halves: a smaller round AND accelerated deployment. Hiring pulled forward, data acquisition deepened, channel and Data Store engines scaled harder in the years the capital is available.
C28: Original plan | D28: Right-sized plan | E28: Change
B29: Series A raise | C29: $15.0M | D29: $8.0M | E29: -$7.0M
B30: Series A dilution | C30: 34.1% | D30: 21.6% | E30: -12.5 pts
B31: Founder ownership (Base) | C31: 48.0% | D31: 57.1% | E31: +9.1 pts
B32: Year 7 revenue (Base) | C32: $46.3M | D32: $60.6M | E32: +$14.3M
B33: Year 7 EBIT (Base) | C33: $22.1M | D33: $31.6M | E33: +$9.5M
B34: Founder proceeds (Base, EBIT) | C34: $54M-$135M | D34: $93M-$232M | E34: materially higher
B36: A smaller round produced a bigger outcome — less dilution, more revenue, higher founder proceeds — because the capital is deployed against growth rather than held. Framing: "We are not raising to survive; we are raising to compress the timeline." Bear reaches $11.8M without capital. Base reaches $60.6M with $8M.
B38: SERIES B · an option, not a plan
B39: The same discipline applied to Series A applies here. Bull enters Year 5 with ~$11.7M cash and ~$6.7M/yr of operating cash flow — the business does not need outside capital to keep growing. Raising $30M against that balance sheet only makes sense if a specific opportunity requires it: a new product line or market, most likely acquisition-shaped.
B41: THE POSITION AT YEAR 5-6 · why options exist at all
C42: Year 5 | D42: Year 6 | E42: What it means
B43: Revenue (Base) | C43: =INDEX(Scenarios!$C$6:$I$8,2,5) -> 23192222 | D43: =INDEX(Scenarios!$C$6:$I$8,2,6) -> 40601094 | E43: Scaled and growing without further capital.
B44: Cash on hand (active scenario) | C44: ='Balance Sheet'!G6 -> 17219101 | D44: ='Balance Sheet'!H6 -> 31775278 | E44: Balance sheet strength to act without diluting.
B45: Operating cash flow (active scenario) | C45: ='Cash Flow'!G11 -> 6413452.7 | D45: ='Cash Flow'!H11 -> 15165193 | E45: Self-funding — any raise is a choice, not a necessity.
B47: THE FRAMING: we are not asking anyone to underwrite Bull. Base is the plan. Bull shows the ceiling if strong execution produces an opportunity worth pursuing — a new product line, a new market, or an acquisition that brings one. The $30M is illustrative of that shape and would be sized to the specific opportunity. Not knowing today which option we exercise is the honest position, and the optionality itself is the point.
B49: Note: the revenue row is hard-wired to Base — the position reached WITHOUT any Series B. Cash and operating cash flow follow the Control toggle, so set it to Base when using this block to judge whether Series B is genuinely optional. That is what makes the option real: the company arrives at that point regardless, then chooses.

Sheet Valuation
B1: Valuation Justification · Seed & Series A
B2: Grounded in 2026 market benchmarks (Carta, Pitchbook-NVCA, Kruze Consulting) and Axionia's own modeled trajectory.
B4: SEED · $6.0M pre-money / $7.0M post-money on a $1.0M raise
B5: Round size vs. market | C5: Axionia's $1.0M raise is pre-seed-sized, not full-seed (2026 seed median raise is $3.1-3.2M). Pre-seed post-money benchmarks run $3M-$10M, median ~$5-7.1M (YC standard cap). Axionia's $7.0M post-money sits mid-band — appropriately calibrated, not aggressive.
B6: Founder premium | C6: 2026 data: 'strong repeat founders' command $8-10M pre-seed caps on pedigree alone. Tom's profile — 20+ years healthcare analytics, Yale MBA, prior VP/SVP roles, $500M+ in underwritten risk products — sits well above the typical first-time-founder profile this benchmark describes. If anything, $6.0M pre-money is conservative relative to what the founder-quality premium alone could support.
B7: Product & traction signal | C7: 2026 pre-seed investors increasingly expect a functional product, not just a deck. Axionia has a working Research Agent pipeline, a defined benchmark-data architecture, and live discovery/reporting engagements already underway — the kind of signal that supports pricing at or above the benchmark midpoint.
B9: SERIES A · $29.0M pre-money / $37.0M post-money on a $8.0M raise
B10: Round size vs. market | C10: 2026 Series A median raise is ~$12M on a $25-50M pre-money range (median ~$45M pre-money). Axionia's round is deliberately smaller than median: $8M at $29M pre-money. The business is cash-generative from Year 2 and funds most of its own growth, so the round is sized to the pre-revenue investment window rather than to market convention — which means materially less dilution (21.6%) for the same growth plan.
B12: REVENUE-MULTIPLE CROSS-CHECK
C13: Basis | D13: Multiple range | E13: Implied pre-money
B14: Trailing Year-3 revenue (Base scenario) | C14: =INDEX(Scenarios!$C$6:$I$8,2,3) -> 3177500 | D14: 8x - 10x | E14: =TEXT(C14*8,"$#,##0,,")&"M - "&TEXT(C14*10,"$#,##0,,")&"M" -> $25M - $32M
B15: Forward Year-4 revenue (Base scenario) | C15: =INDEX(Scenarios!$C$6:$I$8,2,4) -> 10188875 | D15: 3.5x - 4.0x | E15: =TEXT(C15*3.5,"$#,##0,,")&"M - "&TEXT(C15*4,"$#,##0,,")&"M" -> $36M - $41M
B16: Year-3 → Year-4 growth rate | C16: =C15/C14-1 -> 2.2065696
B17: Modeled Series A pre-money | C17: 29000000
B18: 2026 benchmark: >40% YoY growth commands 7-10x ARR; 'strong fundamentals' cluster 8-12x. Axionia's Year-3 to Year-4 growth (above) clears that bar comfortably, and the $29M modeled pre-money sits within the range implied by both the trailing and forward revenue multiples.
B20: The Series A isn't priced on growth rate alone. It's triggered by a specific, falsifiable milestone: a third party paying for the benchmark data. 2026 Series A investors are explicit that the numbers carry the story at this stage — a proven, monetizing data asset is exactly that kind of evidence, and it's evidence a pure revenue-multiple comp doesn't capture.
B21: The Series A isn't priced on growth rate alone. It's triggered by a specific, falsifiable milestone: a third party (health plan, PE diligence, reinsurer) paying for the benchmark data. 2026 Series A investors are explicit that 'the numbers carry the story' at this stage, not the narrative — a proven, monetizing data asset is exactly the kind of evidence this bar describes, and it's evidence a pure revenue-multiple comp doesn't capture.
B23: SOURCES
B24: Carta State of Private Markets, Q3 2025 SaaS spotlight
B25: Pitchbook-NVCA Venture Monitor, Q3 2025
B26: Kruze Consulting 2026 Startup CEO Salary Report
B27: StartupCFO.ai 2026 Founder Salary Report; Warp 2026 Founder Salary Guide
B28: Aggregated 2026 seed/Series A market guides (SaaSUltra, Flowjam, ValueAddVC, Causo Hub)

Sheet Cap Table
B1: Cap Table · illustrative
B2: Single-class common, no option pool modeled. Pricing is illustrative — the point is relative dilution across scenarios, not exact terms.
B4: ROUNDS
C5: Timing | D5: Raise | E5: Pre-money | F5: Post-money | G5: New investor %
B6: Seed (all scenarios) | C6: Year 1 | D6: 1000000 | E6: 6000000 | F6: =D6+E6 -> 7000000 | G6: =D6/F6 -> 0.14285714
B7: Series A (Base & Bull) | C7: Year 4 | D7: 8000000 | E7: 29000000 | F7: =D7+E7 -> 37000000 | G7: =D7/F7 -> 0.21621622
B8: Series B (Bull only — OPTIONAL, illustrative) | C8: Year 5 | D8: 30000000 | E8: 90000000 | F8: =D8+E8 -> 120000000 | G8: =D8/F8 -> 0.25
B10: OWNERSHIP WATERFALL · founder & seed dilute pro-rata at each round
C11: Founder | D11: Seed | E11: Series A | F11: Series B
B12: After Seed | C12: =1-G6 -> 0.85714286 | D12: =G6 -> 0.14285714 | E12: - | F12: -
B13: After Series A | C13: =C12*(1-G7) -> 0.67181467 | D13: =D12*(1-G7) -> 0.11196911 | E13: =G7 -> 0.21621622 | F13: -
B14: After Series B | C14: =C13*(1-G8) -> 0.503861 | D14: =D13*(1-G8) -> 0.083976834 | E14: =E13*(1-G8) -> 0.16216216 | F14: =G8 -> 0.25
B17: FOUNDER OWNERSHIP AT YEAR 7 · by scenario
B18: Bear (Seed only) | C18: =C12 -> 0.85714286
B19: Base (Seed + Series A) | C19: =C13 -> 0.67181467
B20: Bull (Seed + Series A + Series B) | C20: =C14 -> 0.503861
B22: FOUNDER PERFORMANCE EQUITY TRANCHE · in lieu of cash bonus
B23: Tranche size (% of fully-diluted, carved pre-money at Seed) | C23: 0.04
B24: Tied to the same Year-3 milestone that gates the whole model. If earned, Tom's total ownership ends up identical to the no-pool baseline below — this isn't a transfer to someone else, it's a risk-sharing structure: part of his stake becomes contingent rather than guaranteed from day one. If forfeited, the unvested tranche benefits other shareholders proportionally.
C26: Guaranteed | D26: Performance tranche | E26: Total if earned | F26: No-pool baseline | G26: Check
B27: Bear (Seed only) | C27: =C12-$C$23 -> 0.81714286 | D27: =$C$23 -> 0.04 | E27: =C27+D27 -> 0.85714286 | F27: =C18 -> 0.85714286 | G27: =E27-F27 -> 0
B28: Base (Seed + Series A) | C28: =(C12-$C$23)*(1-G7) -> 0.64046332 | D28: =$C$23*(1-G7) -> 0.031351351 | E28: =C28+D28 -> 0.67181467 | F28: =C19 -> 0.67181467 | G28: =E28-F28 -> 0
B29: Bull (Seed + Series A + Series B) | C29: =(C12-$C$23)*(1-G7)*(1-G8) -> 0.48034749 | D29: =$C$23*(1-G7)*(1-G8) -> 0.023513514 | E29: =C29+D29 -> 0.503861 | F29: =C20 -> 0.503861 | G29: =E29-F29 -> 0
B32: EMPLOYEE OPTION POOL · for key hires in Years 2-3
B33: Pool size (% of fully-diluted) | C33: 0.1
B34: WHO PAYS: in a priced round, investors almost always require the pool to be carved from the PRE-money valuation — it dilutes existing shareholders (Tom), not the incoming investor. This is the 'pool shuffle.' NOTE: the timing comparison below shows an identical founder % either way, because pre-money dilution factors multiply and order does not change the product. The real decision is not WHEN to carve, but WHETHER equity is available when key hires arrive — and how large the pool is.
C36: Option A: pool at Seed | D36: Option B: pool at Series A | E36: Difference (nil — see note)
B37: Founder — Bear (Seed only) | C37: =(1-$C$33)*C12 -> 0.77142857 | D37: =C12 -> 0.85714286 | E37: =C37-D37 -> -0.085714286
B38: Founder — Base (Seed + Series A) | C38: =(1-$C$33)*C13 -> 0.6046332 | D38: =C12*(1-$C$33)*(1-G7) -> 0.6046332 | E38: =C38-D38 -> 0
B39: Founder — Bull (Seed + A + B) | C39: =(1-$C$33)*C14 -> 0.4534749 | D39: =C12*(1-$C$33)*(1-G7)*(1-G8) -> 0.4534749 | E39: =C39-D39 -> 0
B41: Pool value at exit (Base, EBIT-multiple range) | C41: =TEXT($C$33*'Exit & Return on Capital'!$C$28,"$#,##0,,")&"M - "&TEXT($C$33*'Exit & Return on Capital'!$E$28,"$#,##0,,")&"M" -> $20M - $51M
B42: what the whole pool is worth to distribute across all early hires
B43: TAKEAWAY: pool SIZE drives founder dilution; pool TIMING does not. Create it early enough that equity is available for Year 2-3 hires, and size it to an actual hiring plan rather than a round-number convention — every unused point stays with existing shareholders.
B44: INDICATIVE GRANT RANGES · % of fully-diluted, at this stage
B45: Partner / co-founder-level | C45: 2% - 8% | D45: Taking founder-level risk and below-market cash. See note below — arguably should NOT come from the pool.
B46: First VP / executive hires | C46: 0.5% - 2% | D46: Head of Sales, Head of Product, senior domain leader.
B47: Early senior individual contributors | C47: 0.1% - 0.5% | D47: First engineers, first analysts, first BD rep.
B48: Support / administrative roles | C48: 0% - 0.1% | D48: Often cash-only at this stage.
B50: Standard terms: 4-year vesting, 1-year cliff. The cliff is the protection — if an early hire does not work out inside year one, nothing vests.
B52: PARTNER GRANT · modeled separately from the pool
...

Sheet Exit & Return on Capital
B1: Exit & Return on Capital
B2: Year 7 exit, both bases shown. EBIT multiple is primary per Tom's view; revenue multiple shown for comparison. Range reflects services-multiple contraction vs. a genuinely protectable, strategic-buyer premium.
B4: EXIT MULTIPLE ASSUMPTIONS · Year 7, Low / Mid / High
C5: Low | D5: Mid | E5: High
B6: Revenue multiple | C6: 3 | D6: 5 | E6: 8
B7: EBIT multiple (primary basis) | C7: 6 | D7: 10 | E7: 15
B9: Likely acquirer: a distribution channel (broker/consultant) whose economics this business threatens — a defensive strategic buyer, not primarily a financial one.
B11: YEAR 7 FINANCIALS · fixed per scenario, not toggle-dependent
C12: Bear | D12: Base | E12: Bull
B13: Revenue | C13: =Scenarios!I6 -> 11816789 | D13: =Scenarios!I7 -> 60581809 | E13: =Scenarios!I8 -> 91343109
B14: COGS (bottom-up analyst build, per scenario) | C14: ='COGS & Overhead Build'!C96 -> 1669900 | D14: ='COGS & Overhead Build'!D96 -> 6584600 | E14: ='COGS & Overhead Build'!E96 -> 9841400
B15: Total operating expense (S&M + Product&Eng + G&A) | C15: ='S&M Build'!I16+'Product & Data Eng Build'!I15+'G&A & Exec Comp Build'!I24 -> 3840000 | D15: ='S&M Build'!I23+'Product & Data Eng Build'!I21+'G&A & Exec Comp Build'!I25 -> 19970000 | E15: ='S&M Build'!I30+'Product & Data Eng Build'!I27+'G&A & Exec Comp Build'!I26 -> 31670000
B16: EBIT (pre-D&A) | C16: =C13-C14-C15 -> 6306889 | D16: =D13-D14-D15 -> 34027209 | E16: =E13-E14-E15 -> 49831709
B17: excludes the minor equipment D&A line — immaterial at this scale (~1-2% of EBIT). COGS above is the bottom-up analyst build (COGS & Overhead Build, rows 87-98), the same basis the P&L uses — not the Scenarios-tab gross-margin assumption, which is a legacy input retained only for reference.
B19: EXIT ENTERPRISE VALUE · Revenue multiple
C20: Low | D20: Mid | E20: High
B21: Bear | C21: =C13*$C$6 -> 35450367 | D21: =C13*$D$6 -> 59083945 | E21: =C13*$E$6 -> 94534312
B22: Base | C22: =D13*$C$6 -> 181745427 | D22: =D13*$D$6 -> 302909045 | E22: =D13*$E$6 -> 484654472
B23: Bull | C23: =E13*$C$6 -> 274029327 | D23: =E13*$D$6 -> 456715545 | E23: =E13*$E$6 -> 730744872
B25: EXIT ENTERPRISE VALUE · EBIT multiple (primary)
C26: Low | D26: Mid | E26: High
B27: Bear | C27: =C16*$C$7 -> 37841334 | D27: =C16*$D$7 -> 63068890 | E27: =C16*$E$7 -> 94603335
B28: Base | C28: =D16*$C$7 -> 204163254 | D28: =D16*$D$7 -> 340272090 | E28: =D16*$E$7 -> 510408135
B29: Bull | C29: =E16*$C$7 -> 298990254 | D29: =E16*$D$7 -> 498317090 | E29: =E16*$E$7 -> 747475635
B31: RETURNS BY INVESTOR CLASS · EBIT multiple (primary basis)
B33: BEAR (Seed only, 7-year hold)
C34: Capital in | D34: Exit % | E34: Proceeds (low - high) | F34: MOIC (low - high) | G34: IRR (low - high)
B35: Founder | C35: n/a — sweat equity | D35: ='Cap Table'!C62 -> 0.72857143 | E35: =TEXT($C$27*D35,"$#,##0,,")&"M - "&TEXT($E$27*D35,"$#,##0,,")&"M" -> $28M - $69M | F35: — | G35: —
B36: Seed | C36: ='Cap Table'!$D$6 -> 1000000 | D36: ='Cap Table'!F62 -> 0.14285714 | E36: =TEXT($C$27*D36,"$#,##0,,")&"M - "&TEXT($E$27*D36,"$#,##0,,")&"M" -> $5M - $14M | F36: =TEXT($C$27*D36/$C$36,"0.0")&"x - "&TEXT($E$27*D36/$C$36,"0.0")&"x" -> 5.4x - 13.5x | G36: =TEXT(($C$27*D36/$C$36)^(1/7)-1,"0%")&" - "&TEXT(($E$27*D36/$C$36)^(1/7)-1,"0%") -> 27% - 45%
B37: Option pool | C37: carved pre-money | D37: ='Cap Table'!D62 -> 0.085714286 | E37: =TEXT($C$27*D37,"$#,##0,,")&"M - "&TEXT($E$27*D37,"$#,##0,,")&"M" -> $3M - $8M | F37: — | G37: —
B38: BASE (Seed + Series A)
C39: Capital in | D39: Exit % | E39: Proceeds (low - high) | F39: MOIC (low - high) | G39: IRR (low - high)
B40: Founder | C40: n/a — sweat equity | D40: ='Cap Table'!C63 -> 0.57104247 | E40: =TEXT($C$28*D40,"$#,##0,,")&"M - "&TEXT($E$28*D40,"$#,##0,,")&"M" -> $117M - $291M | F40: — | G40: —
B41: Seed | C41: ='Cap Table'!$D$6 -> 1000000 | D41: ='Cap Table'!F63 -> 0.11196911 | E41: =TEXT($C$28*D41,"$#,##0,,")&"M - "&TEXT($E$28*D41,"$#,##0,,")&"M" -> $23M - $57M | F41: =TEXT($C$28*D41/$C$41,"0.0")&"x - "&TEXT($E$28*D41/$C$41,"0.0")&"x" -> 22.9x - 57.1x | G41: =TEXT(($C$28*D41/$C$41)^(1/7)-1,"0%")&" - "&TEXT(($E$28*D41/$C$41)^(1/7)-1,"0%") -> 56% - 78%
B42: Series A | C42: ='Cap Table'!$D$7 -> 8000000 | D42: ='Cap Table'!G63 -> 0.21621622 | E42: =TEXT($C$28*D42,"$#,##0,,")&"M - "&TEXT($E$28*D42,"$#,##0,,")&"M" -> $44M - $110M | F42: =TEXT($C$28*D42/$C$42,"0.0")&"x - "&TEXT($E$28*D42/$C$42,"0.0")&"x" -> 5.5x - 13.8x | G42: =TEXT(($C$28*D42/$C$42)^(1/4)-1,"0%")&" - "&TEXT(($E$28*D42/$C$42)^(1/4)-1,"0%") -> 53% - 93%
B43: Option pool | C43: carved pre-money | D43: ='Cap Table'!D63 -> 0.067181467 | E43: =TEXT($C$28*D43,"$#,##0,,")&"M - "&TEXT($E$28*D43,"$#,##0,,")&"M" -> $14M - $34M | F43: — | G43: —
B44: BULL (Seed + Series A + Series B)
C45: Capital in | D45: Exit % | E45: Proceeds (low - high) | F45: MOIC (low - high) | G45: IRR (low - high)
B46: Founder | C46: n/a — sweat equity | D46: ='Cap Table'!C64 -> 0.42828185 | E46: =TEXT($C$29*D46,"$#,##0,,")&"M - "&TEXT($E$29*D46,"$#,##0,,")&"M" -> $128M - $320M | F46: — | G46: —
B47: Seed | C47: ='Cap Table'!$D$6 -> 1000000 | D47: ='Cap Table'!F64 -> 0.083976834 | E47: =TEXT($C$29*D47,"$#,##0,,")&"M - "&TEXT($E$29*D47,"$#,##0,,")&"M" -> $25M - $63M | F47: =TEXT($C$29*D47/$C$47,"0.0")&"x - "&TEXT($E$29*D47/$C$47,"0.0")&"x" -> 25.1x - 62.8x | G47: =TEXT(($C$29*D47/$C$47)^(1/7)-1,"0%")&" - "&TEXT(($E$29*D47/$C$47)^(1/7)-1,"0%") -> 58% - 81%
...

Sheet P&L
B1: Income Statement
B2: Product/data-eng and data-acquisition spend expensed as incurred (policy choice — flagged below). D&A is the minor equipment/infra schedule only.
C4: Year 1 | D4: Year 2 | E4: Year 3 | F4: Year 4 | G4: Year 5 | H4: Year 6 | I4: Year 7
B5: Revenue | C5: ='WC & Capex'!C15 -> 348750 | D5: ='WC & Capex'!D15 -> 1342125 | E5: ='WC & Capex'!E15 -> 3177500 | F5: ='WC & Capex'!F15 -> 10188875 | G5: ='WC & Capex'!G15 -> 23192222 | H5: ='WC & Capex'!H15 -> 40601094 | I5: ='WC & Capex'!I15 -> 60581809
B6: Cost of goods sold | C6: =-'WC & Capex'!C16 -> -12000 | D6: =-'WC & Capex'!D16 -> -153600 | E6: =-'WC & Capex'!E16 -> -967800 | F6: =-'WC & Capex'!F16 -> -2118300 | G6: =-'WC & Capex'!G16 -> -3776200 | H6: =-'WC & Capex'!H16 -> -5180400 | I6: =-'WC & Capex'!I16 -> -6584600
B7: Gross profit | C7: =C5+C6 -> 336750 | D7: =D5+D6 -> 1188525 | E7: =E5+E6 -> 2209700 | F7: =F5+F6 -> 8070575 | G7: =G5+G6 -> 19416022 | H7: =H5+H6 -> 35420694 | I7: =I5+I6 -> 53997209
B8: gross margin | C8: =C7/C5 -> 0.9655914 | D8: =D7/D5 -> 0.88555462 | E8: =E7/E5 -> 0.69542093 | F8: =F7/F5 -> 0.79209677 | G8: =G7/G5 -> 0.83717817 | H8: =H7/H5 -> 0.87240738 | I8: =I7/I5 -> 0.89131061
B10: Sales & marketing | C10: =-CHOOSE(Control!$C$8,'S&M Build'!C16,'S&M Build'!C23,'S&M Build'!C30) -> -20000 | D10: =-CHOOSE(Control!$C$8,'S&M Build'!D16,'S&M Build'!D23,'S&M Build'!D30) -> -250000 | E10: =-CHOOSE(Control!$C$8,'S&M Build'!E16,'S&M Build'!E23,'S&M Build'!E30) -> -475000 | F10: =-CHOOSE(Control!$C$8,'S&M Build'!F16,'S&M Build'!F23,'S&M Build'!F30) -> -3320000 | G10: =-CHOOSE(Control!$C$8,'S&M Build'!G16,'S&M Build'!G23,'S&M Build'!G30) -> -5660000 | H10: =-CHOOSE(Control!$C$8,'S&M Build'!H16,'S&M Build'!H23,'S&M Build'!H30) -> -7765000 | I10: =-CHOOSE(Control!$C$8,'S&M Build'!I16,'S&M Build'!I23,'S&M Build'!I30) -> -9620000
B11: Product, data engineering & authority | C11: =-CHOOSE(Control!$C$8,'Product & Data Eng Build'!C15,'Product & Data Eng Build'!C21,'Product & Data Eng Build'!C27) -> -15000 | D11: =-CHOOSE(Control!$C$8,'Product & Data Eng Build'!D15,'Product & Data Eng Build'!D21,'Product & Data Eng Build'!D27) -> -415000 | E11: =-CHOOSE(Control!$C$8,'Product & Data Eng Build'!E15,'Product & Data Eng Build'!E21,'Product & Data Eng Build'!E27) -> -415000 | F11: =-CHOOSE(Control!$C$8,'Product & Data Eng Build'!F15,'Product & Data Eng Build'!F21,'Product & Data Eng Build'!F27) -> -2525000 | G11: =-CHOOSE(Control!$C$8,'Product & Data Eng Build'!G15,'Product & Data Eng Build'!G21,'Product & Data Eng Build'!G27) -> -4735000 | H11: =-CHOOSE(Control!$C$8,'Product & Data Eng Build'!H15,'Product & Data Eng Build'!H21,'Product & Data Eng Build'!H27) -> -6495000 | I11: =-CHOOSE(Control!$C$8,'Product & Data Eng Build'!I15,'Product & Data Eng Build'!I21,'Product & Data Eng Build'!I27) -> -8140000
B12: General & administrative | C12: =-CHOOSE(Control!$C$8,'G&A & Exec Comp Build'!C24,'G&A & Exec Comp Build'!C25,'G&A & Exec Comp Build'!C26) -> -429400 | D12: =-CHOOSE(Control!$C$8,'G&A & Exec Comp Build'!D24,'G&A & Exec Comp Build'!D25,'G&A & Exec Comp Build'!D26) -> -460700 | E12: =-CHOOSE(Control!$C$8,'G&A & Exec Comp Build'!E24,'G&A & Exec Comp Build'!E25,'G&A & Exec Comp Build'!E26) -> -465000 | F12: =-CHOOSE(Control!$C$8,'G&A & Exec Comp Build'!F24,'G&A & Exec Comp Build'!F25,'G&A & Exec Comp Build'!F26) -> -780000 | G12: =-CHOOSE(Control!$C$8,'G&A & Exec Comp Build'!G24,'G&A & Exec Comp Build'!G25,'G&A & Exec Comp Build'!G26) -> -1380000 | H12: =-CHOOSE(Control!$C$8,'G&A & Exec Comp Build'!H24,'G&A & Exec Comp Build'!H25,'G&A & Exec Comp Build'!H26) -> -1795000 | I12: =-CHOOSE(Control!$C$8,'G&A & Exec Comp Build'!I24,'G&A & Exec Comp Build'!I25,'G&A & Exec Comp Build'!I26) -> -2210000
B13: Total operating expense | C13: =SUM(C10:C12) -> -464400 | D13: =SUM(D10:D12) -> -1125700 | E13: =SUM(E10:E12) -> -1355000 | F13: =SUM(F10:F12) -> -6625000 | G13: =SUM(G10:G12) -> -11775000 | H13: =SUM(H10:H12) -> -16055000 | I13: =SUM(I10:I12) -> -19970000
B15: EBITDA | C15: =C7+C13 -> -127650 | D15: =D7+D13 -> 62825 | E15: =E7+E13 -> 854700 | F15: =F7+F13 -> 1445575 | G15: =G7+G13 -> 7641022.5 | H15: =H7+H13 -> 19365694 | I15: =I7+I13 -> 34027209
B16: Depreciation & amortization | C16: =-'WC & Capex'!C27 -> -3333.3333 | D16: =-'WC & Capex'!D27 -> -4333.3333 | E16: =-'WC & Capex'!E27 -> -20220.833 | F16: =-'WC & Capex'!F27 -> -67831.875 | G16: =-'WC & Capex'!G27 -> -182792.99 | H16: =-'WC & Capex'!H27 -> -369910.96 | I16: =-'WC & Capex'!I27 -> -621875.63
B17: EBIT | C17: =C15+C16 -> -130983.33 | D17: =D15+D16 -> 58491.667 | E17: =E15+E16 -> 834479.17 | F17: =F15+F16 -> 1377743.1 | G17: =G15+G16 -> 7458229.5 | H17: =H15+H16 -> 18995783 | I17: =I15+I16 -> 33405333
B18: EBIT margin | C18: =C17/C5 -> -0.37557945 | D18: =D17/D5 -> 0.043581385 | E18: =E17/E5 -> 0.2626213 | F18: =F17/F5 -> 0.13522034 | G18: =G17/G5 -> 0.32158322 | H18: =H17/H5 -> 0.46786383 | I18: =I17/I5 -> 0.55140865
B19: Interest income (on beginning cash) | C19: =0 -> 0 | D19: ='Balance Sheet'!C6*'WC & Capex'!$C$10 -> 35869.151 | E19: ='Balance Sheet'!D6*'WC & Capex'!$C$10 -> 41792.273 | F19: ='Balance Sheet'!E6*'WC & Capex'!$C$10 -> 69438.115 | G19: ='Balance Sheet'!F6*'WC & Capex'!$C$10 -> 446141.27 | H19: ='Balance Sheet'!G6*'WC & Capex'!$C$10 -> 688764.05 | I19: ='Balance Sheet'!H6*'WC & Capex'!$C$10 -> 1271011.1
B20: Pre-tax income | C20: =C17+C19 -> -130983.33 | D20: =D17+D19 -> 94360.817 | E20: =E17+E19 -> 876271.44 | F20: =F17+F19 -> 1447181.2 | G20: =G17+G19 -> 7904370.8 | H20: =H17+H19 -> 19684547 | I20: =I17+I19 -> 34676344
B21: TAX (NOL carryforward)
B22: NOL balance, beginning | C22: 0 | D22: =C23 -> 130983.33 | E22: =D23 -> 36622.516 | F22: =E23 -> 0 | G22: =F23 -> 0 | H22: =G23 -> 0 | I22: =H23 -> 0
B23: NOL balance, ending | C23: =C22+MAX(0,-C20)-MIN(C22,MAX(0,C20)) -> 130983.33 | D23: =D22+MAX(0,-D20)-MIN(D22,MAX(0,D20)) -> 36622.516 | E23: =E22+MAX(0,-E20)-MIN(E22,MAX(0,E20)) -> 0 | F23: =F22+MAX(0,-F20)-MIN(F22,MAX(0,F20)) -> 0 | G23: =G22+MAX(0,-G20)-MIN(G22,MAX(0,G20)) -> 0 | H23: =H22+MAX(0,-H20)-MIN(H22,MAX(0,H20)) -> 0 | I23: =I22+MAX(0,-I20)-MIN(I22,MAX(0,I20)) -> 0
B24: Income tax provision | C24: =MAX(0,C20-C22)*'WC & Capex'!$C$11 -> 0 | D24: =MAX(0,D20-D22)*'WC & Capex'!$C$11 -> 0 | E24: =MAX(0,E20-E22)*'WC & Capex'!$C$11 -> 218308.72 | F24: =MAX(0,F20-F22)*'WC & Capex'!$C$11 -> 376267.12 | G24: =MAX(0,G20-G22)*'WC & Capex'!$C$11 -> 2055136.4 | H24: =MAX(0,H20-H22)*'WC & Capex'!$C$11 -> 5117982.3 | I24: =MAX(0,I20-I22)*'WC & Capex'!$C$11 -> 9015849.6
B25: Net income | C25: =C20-C24 -> -130983.33 | D25: =D20-D24 -> 94360.817 | E25: =E20-E24 -> 657962.72 | F25: =F20-F24 -> 1070914.1 | G25: =G20-G24 -> 5849234.4 | H25: =H20-H24 -> 14566565 | I25: =I20-I24 -> 25660495
B26: net margin | C26: =C25/C5 -> -0.37557945 | D26: =D25/D5 -> 0.070307026 | E26: =E25/E5 -> 0.20706931 | F26: =F25/F5 -> 0.10510622 | G26: =G25/G5 -> 0.25220672 | H26: =H25/H5 -> 0.35877272 | I26: =I25/I5 -> 0.42356766
B28: ▲ Policy: product/eng + data-acquisition spend expensed as incurred, not capitalized — a conservative, transparency-first choice.
B29: Capitalizing more of this spend would raise near-term EBITDA and support a different valuation framing — open to revisiting.

Sheet Cash Flow
B1: Statement of Cash Flows
B2: Indirect method. Working-capital deltas and financing pull from the WC & Capex and Scenarios tabs.
C4: Year 1 | D4: Year 2 | E4: Year 3 | F4: Year 4 | G4: Year 5 | H4: Year 6 | I4: Year 7
B5: OPERATING ACTIVITIES
B6: Net income | C6: ='P&L'!C25 -> -130983.33 | D6: ='P&L'!D25 -> 94360.817 | E6: ='P&L'!E25 -> 657962.72 | F6: ='P&L'!F25 -> 1070914.1 | G6: ='P&L'!G25 -> 5849234.4 | H6: ='P&L'!H25 -> 14566565 | I6: ='P&L'!I25 -> 25660495
B7: + Depreciation & amortization | C7: ='WC & Capex'!C27 -> 3333.3333 | D7: ='WC & Capex'!D27 -> 4333.3333 | E7: ='WC & Capex'!E27 -> 20220.833 | F7: ='WC & Capex'!F27 -> 67831.875 | G7: ='WC & Capex'!G27 -> 182792.99 | H7: ='WC & Capex'!H27 -> 369910.96 | I7: ='WC & Capex'!I27 -> 621875.63
B8: (Increase) / decrease in AR | C8: =-'WC & Capex'!C21 -> -23886.986 | D8: =-('WC & Capex'!D21-'WC & Capex'!C21) -> -68039.384 | E8: =-('WC & Capex'!E21-'WC & Capex'!D21) -> -125710.62 | F8: =-('WC & Capex'!F21-'WC & Capex'!E21) -> -480231.16 | G8: =-('WC & Capex'!G21-'WC & Capex'!F21) -> -890640.24 | H8: =-('WC & Capex'!H21-'WC & Capex'!G21) -> -1192388.5 | I8: =-('WC & Capex'!I21-'WC & Capex'!H21) -> -1368542.1
B9: Increase / (decrease) in deferred revenue | C9: ='WC & Capex'!C22 -> 19109.589 | D9: ='WC & Capex'!D22-'WC & Capex'!C22 -> 54431.507 | E9: ='WC & Capex'!E22-'WC & Capex'!D22 -> 100568.49 | F9: ='WC & Capex'!F22-'WC & Capex'!E22 -> 384184.93 | G9: ='WC & Capex'!G22-'WC & Capex'!F22 -> 712512.19 | H9: ='WC & Capex'!H22-'WC & Capex'!G22 -> 953910.78 | I9: ='WC & Capex'!I22-'WC & Capex'!H22 -> 1094833.7
B10: Increase / (decrease) in AP | C10: ='WC & Capex'!C23 -> 39156.164 | D10: ='WC & Capex'!D23-'WC & Capex'!C23 -> 65991.781 | E10: ='WC & Capex'!E23-'WC & Capex'!D23 -> 85767.123 | F10: ='WC & Capex'!F23-'WC & Capex'!E23 -> 527712.33 | G10: ='WC & Capex'!G23-'WC & Capex'!F23 -> 559553.42 | H10: ='WC & Capex'!H23-'WC & Capex'!G23 -> 467194.52 | I10: ='WC & Capex'!I23-'WC & Capex'!H23 -> 437194.52
B11: Cash from operations | C11: =SUM(C6:C10) -> -93271.233 | D11: =SUM(D6:D10) -> 151078.05 | E11: =SUM(E6:E10) -> 738808.55 | F11: =SUM(F6:F10) -> 1570412.1 | G11: =SUM(G6:G10) -> 6413452.7 | H11: =SUM(H6:H10) -> 15165193 | I11: =SUM(I6:I10) -> 26445857
B13: INVESTING ACTIVITIES
B14: Capital expenditures | C14: =-'WC & Capex'!C26 -> -10000 | D14: =-'WC & Capex'!D26 -> -3000 | E14: =-'WC & Capex'!E26 -> -47662.5 | F14: =-'WC & Capex'!F26 -> -152833.12 | G14: =-'WC & Capex'!G26 -> -347883.34 | H14: =-'WC & Capex'!H26 -> -609016.41 | I14: =-'WC & Capex'!I26 -> -908727.14
B15: Cash from investing | C15: =C14 -> -10000 | D15: =D14 -> -3000 | E15: =E14 -> -47662.5 | F15: =F14 -> -152833.12 | G15: =G14 -> -347883.34 | H15: =H14 -> -609016.41 | I15: =I14 -> -908727.14
B17: FINANCING ACTIVITIES
B18: Equity capital raised | C18: =INDEX(Scenarios!$C$21:$I$23,Control!$C$8,1) -> 1000000 | D18: =INDEX(Scenarios!$C$21:$I$23,Control!$C$8,2) -> 0 | E18: =INDEX(Scenarios!$C$21:$I$23,Control!$C$8,3) -> 0 | F18: =INDEX(Scenarios!$C$21:$I$23,Control!$C$8,4) -> 8000000 | G18: =INDEX(Scenarios!$C$21:$I$23,Control!$C$8,5) -> 0 | H18: =INDEX(Scenarios!$C$21:$I$23,Control!$C$8,6) -> 0 | I18: =INDEX(Scenarios!$C$21:$I$23,Control!$C$8,7) -> 0
B19: Cash from financing | C19: =C18 -> 1000000 | D19: =D18 -> 0 | E19: =E18 -> 0 | F19: =F18 -> 8000000 | G19: =G18 -> 0 | H19: =H18 -> 0 | I19: =I18 -> 0
B21: Net change in cash | C21: =C11+C15+C19 -> 896728.77 | D21: =D11+D15+D19 -> 148078.05 | E21: =E11+E15+E19 -> 691146.05 | F21: =F11+F15+F19 -> 9417579 | G21: =G11+G15+G19 -> 6065569.4 | H21: =H11+H15+H19 -> 14556176 | I21: =I11+I15+I19 -> 25537130
B22: Beginning cash | C22: 0 | D22: =C23 -> 896728.77 | E22: =D23 -> 1044806.8 | F22: =E23 -> 1735952.9 | G22: =F23 -> 11153532 | H22: =G23 -> 17219101 | I22: =H23 -> 31775278
B23: Ending cash | C23: =C22+C21 -> 896728.77 | D23: =D22+D21 -> 1044806.8 | E23: =E22+E21 -> 1735952.9 | F23: =F22+F21 -> 11153532 | G23: =G22+G21 -> 17219101 | H23: =H22+H21 -> 31775278 | I23: =I22+I21 -> 57312407

Sheet Balance Sheet
B1: Balance Sheet
B2: Period-end. Row 20 is a check — must read zero every year. No option pool / minority interest modeled.
C4: Year 1 | D4: Year 2 | E4: Year 3 | F4: Year 4 | G4: Year 5 | H4: Year 6 | I4: Year 7
B5: ASSETS
B6: Cash | C6: ='Cash Flow'!C23 -> 896728.77 | D6: ='Cash Flow'!D23 -> 1044806.8 | E6: ='Cash Flow'!E23 -> 1735952.9 | F6: ='Cash Flow'!F23 -> 11153532 | G6: ='Cash Flow'!G23 -> 17219101 | H6: ='Cash Flow'!H23 -> 31775278 | I6: ='Cash Flow'!I23 -> 57312407
B7: Accounts receivable | C7: ='WC & Capex'!C21 -> 23886.986 | D7: ='WC & Capex'!D21 -> 91926.37 | E7: ='WC & Capex'!E21 -> 217636.99 | F7: ='WC & Capex'!F21 -> 697868.15 | G7: ='WC & Capex'!G21 -> 1588508.4 | H7: ='WC & Capex'!H21 -> 2780896.9 | I7: ='WC & Capex'!I21 -> 4149439
B8: PP&E, net | C8: ='WC & Capex'!C28 -> 6666.6667 | D8: ='WC & Capex'!D28 -> 5333.3333 | E8: ='WC & Capex'!E28 -> 32775 | F8: ='WC & Capex'!F28 -> 117776.25 | G8: ='WC & Capex'!G28 -> 282866.6 | H8: ='WC & Capex'!H28 -> 521972.05 | I8: ='WC & Capex'!I28 -> 808823.56
B9: Total assets | C9: =SUM(C6:C8) -> 927282.42 | D9: =SUM(D6:D8) -> 1142066.5 | E9: =SUM(E6:E8) -> 1986364.9 | F9: =SUM(F6:F8) -> 11969176 | G9: =SUM(G6:G8) -> 19090476 | H9: =SUM(H6:H8) -> 35078147 | I9: =SUM(I6:I8) -> 62270670
B11: LIABILITIES
B12: Accounts payable | C12: ='WC & Capex'!C23 -> 39156.164 | D12: ='WC & Capex'!D23 -> 105147.95 | E12: ='WC & Capex'!E23 -> 190915.07 | F12: ='WC & Capex'!F23 -> 718627.4 | G12: ='WC & Capex'!G23 -> 1278180.8 | H12: ='WC & Capex'!H23 -> 1745375.3 | I12: ='WC & Capex'!I23 -> 2182569.9
B13: Deferred revenue | C13: ='WC & Capex'!C22 -> 19109.589 | D13: ='WC & Capex'!D22 -> 73541.096 | E13: ='WC & Capex'!E22 -> 174109.59 | F13: ='WC & Capex'!F22 -> 558294.52 | G13: ='WC & Capex'!G22 -> 1270806.7 | H13: ='WC & Capex'!H22 -> 2224717.5 | I13: ='WC & Capex'!I22 -> 3319551.2
B14: Total liabilities | C14: =C12+C13 -> 58265.753 | D14: =D12+D13 -> 178689.04 | E14: =E12+E13 -> 365024.66 | F14: =F12+F13 -> 1276921.9 | G14: =G12+G13 -> 2548987.5 | H14: =H12+H13 -> 3970092.8 | I14: =I12+I13 -> 5502121
B16: EQUITY
B17: Paid-in capital (cumulative) | C17: ='Cash Flow'!C18 -> 1000000 | D17: =C17+'Cash Flow'!D18 -> 1000000 | E17: =D17+'Cash Flow'!E18 -> 1000000 | F17: =E17+'Cash Flow'!F18 -> 9000000 | G17: =F17+'Cash Flow'!G18 -> 9000000 | H17: =G17+'Cash Flow'!H18 -> 9000000 | I17: =H17+'Cash Flow'!I18 -> 9000000
B18: Retained earnings (accumulated deficit) | C18: ='P&L'!C25 -> -130983.33 | D18: =C18+'P&L'!D25 -> -36622.516 | E18: =D18+'P&L'!E25 -> 621340.2 | F18: =E18+'P&L'!F25 -> 1692254.3 | G18: =F18+'P&L'!G25 -> 7541488.7 | H18: =G18+'P&L'!H25 -> 22108054 | I18: =H18+'P&L'!I25 -> 47768549
B19: Total equity | C19: =C17+C18 -> 869016.67 | D19: =D17+D18 -> 963377.48 | E19: =E17+E18 -> 1621340.2 | F19: =F17+F18 -> 10692254 | G19: =G17+G18 -> 16541489 | H19: =H17+H18 -> 31108054 | I19: =I17+I18 -> 56768549
B20: Check (assets − liabilities − equity) | C20: =C9-C14-C19 -> 0 | D20: =D9-D14-D19 -> 0 | E20: =E9-E14-E19 -> 0 | F20: =F9-F14-F19 -> 0 | G20: =G9-G14-G19 -> 0 | H20: =H9-H14-H19 -> 0 | I20: =I9-I14-I19 -> 0

Sheet Scenarios
B1: Scenario Data
B2: Years 1-3 identical across all three — funded by the $1M raised now. Divergence starts Year 4, based on Year-3 results.
C4: Year 1 | D4: Year 2 | E4: Year 3 | F4: Year 4 | G4: Year 5 | H4: Year 6 | I4: Year 7
B5: REVENUE ($)
B6: Bear | C6: ='Revenue Build - Pressure Test'!C115 -> 348750 | D6: ='Revenue Build - Pressure Test'!D115 -> 1342125 | E6: ='Revenue Build - Pressure Test'!E115 -> 3177500 | F6: ='Revenue Build - Pressure Test'!F115 -> 5081000 | G6: ='Revenue Build - Pressure Test'!G115 -> 6862422.5 | H6: ='Revenue Build - Pressure Test'!H115 -> 9305516.8 | I6: ='Revenue Build - Pressure Test'!I115 -> 11816789
B7: Base | C7: ='Revenue Build - Pressure Test'!C152 -> 348750 | D7: ='Revenue Build - Pressure Test'!D152 -> 1342125 | E7: ='Revenue Build - Pressure Test'!E152 -> 3177500 | F7: ='Revenue Build - Pressure Test'!F152 -> 10188875 | G7: ='Revenue Build - Pressure Test'!G152 -> 23192222 | H7: ='Revenue Build - Pressure Test'!H152 -> 40601094 | I7: ='Revenue Build - Pressure Test'!I152 -> 60581809
B8: Bull | C8: ='Revenue Build - Pressure Test'!C173 -> 348750 | D8: ='Revenue Build - Pressure Test'!D173 -> 1342125 | E8: ='Revenue Build - Pressure Test'!E173 -> 3177500 | F8: ='Revenue Build - Pressure Test'!F173 -> 10019250 | G8: ='Revenue Build - Pressure Test'!G173 -> 27953722 | H8: ='Revenue Build - Pressure Test'!H173 -> 56027882 | I8: ='Revenue Build - Pressure Test'!I173 -> 91343109
B10: GROSS MARGIN · LEGACY INPUT — no longer drives any statement; COGS is built bottom-up on COGS & Overhead Build
B11: Bear | C11: 0.42 | D11: 0.55 | E11: 0.64 | F11: 0.7 | G11: 0.75 | H11: 0.77 | I11: 0.79
B12: Base | C12: 0.42 | D12: 0.55 | E12: 0.64 | F12: 0.66 | G12: 0.71 | H12: 0.75 | I12: 0.78
B13: Bull | C13: 0.42 | D13: 0.55 | E13: 0.64 | F13: 0.65 | G13: 0.72 | H13: 0.77 | I13: 0.82
B15: TOTAL OPERATING EXPENSE ($) · SUPERSEDED — kept for reference only
B16: Bear | C16: 550000 | D16: 1350000 | E16: 3000000 | F16: 4900000 | G16: 7300000 | H16: 9800000 | I16: 12500000
B17: Base | C17: 550000 | D17: 1350000 | E17: 3000000 | F17: 11400000 | G17: 21700000 | H17: 29700000 | I17: 34000000
B18: Bull | C18: 550000 | D18: 1350000 | E18: 3200000 | F18: 14500000 | G18: 29500000 | H18: 44500000 | I18: 50000000
B20: CAPITAL RAISED THIS YEAR ($)
B21: Bear | C21: 1000000 | D21: 0 | E21: 0 | F21: 0 | G21: 0 | H21: 0 | I21: 0
B22: Base | C22: 1000000 | D22: 0 | E22: 0 | F22: 8000000 | G22: 0 | H22: 0 | I22: 0
B23: Bull | C23: 1000000 | D23: 0 | E23: 0 | F23: 8000000 | G23: 30000000 | H23: 0 | I23: 0
B25: Bear
B26: Base
B27: Bull

Sheet Revenue Build - Pressure Test
B1: Revenue Build — Bottom-Up Pressure Test
B2: All 7 years. Client-count and seasonal-cohort driven. Follows the Control toggle for Years 4-7, where scenarios diverge.
C4: Year 1 | D4: Year 2 | E4: Year 3 | F4: Year 4 | G4: Year 5 | H4: Year 6 | I4: Year 7
B6: PRICING & COHORT TIMING · configurable
B7: Monthly revenue per client — low | C7: 4000
B8: Monthly revenue per client — mid (used below) | C8: 4500
B9: Monthly revenue per client — high | C9: 5000
B10: implied annual ACV at mid rate | C10: =C8*12 -> 54000
B12: Jan-Mar cohort — avg months active in signing year | C12: 10
B13: Jul-Aug cohort — avg months active in signing year | C13: 5
B14: Jan-Mar cohort share of new adds | C14: 0.55
B15: Jul-Aug cohort share | C15: =1-C14 -> 0.45
B16: blended avg months active (check vs. your ~9mo target) | C16: =C14*C12+C15*C13 -> 7.75
B18: BD rep quota (new clients/rep/year) | C18: 15
B19: Enterprise rep quota | C19: 5
B20: VP Sales quota (player-coach) | C20: 3
B21: Retention rate, Years 1-3 | C21: 1
B22: Retention rate, Years 4-7 | C22: 0.9
B24: SALES CAPACITY · follows the Control toggle (Y1-3 identical across scenarios, Y4-7 diverge)
B25: Founder-sourced new clients | C25: 10 | D25: 8 | E25: 6 | F25: 4 | G25: 3 | H25: 2 | I25: 2
B26: BD reps | C26: =CHOOSE(Control!$C$8,'S&M Build'!C12,'S&M Build'!C19,'S&M Build'!C26) -> 0 | D26: =CHOOSE(Control!$C$8,'S&M Build'!D12,'S&M Build'!D19,'S&M Build'!D26) -> 1 | E26: =CHOOSE(Control!$C$8,'S&M Build'!E12,'S&M Build'!E19,'S&M Build'!E26) -> 2 | F26: =CHOOSE(Control!$C$8,'S&M Build'!F12,'S&M Build'!F19,'S&M Build'!F26) -> 7 | G26: =CHOOSE(Control!$C$8,'S&M Build'!G12,'S&M Build'!G19,'S&M Build'!G26) -> 11 | H26: =CHOOSE(Control!$C$8,'S&M Build'!H12,'S&M Build'!H19,'S&M Build'!H26) -> 14 | I26: =CHOOSE(Control!$C$8,'S&M Build'!I12,'S&M Build'!I19,'S&M Build'!I26) -> 16
B27: Enterprise reps | C27: =CHOOSE(Control!$C$8,'S&M Build'!C13,'S&M Build'!C20,'S&M Build'!C27) -> 0 | D27: =CHOOSE(Control!$C$8,'S&M Build'!D13,'S&M Build'!D20,'S&M Build'!D27) -> 0 | E27: =CHOOSE(Control!$C$8,'S&M Build'!E13,'S&M Build'!E20,'S&M Build'!E27) -> 0 | F27: =CHOOSE(Control!$C$8,'S&M Build'!F13,'S&M Build'!F20,'S&M Build'!F27) -> 6 | G27: =CHOOSE(Control!$C$8,'S&M Build'!G13,'S&M Build'!G20,'S&M Build'!G27) -> 10 | H27: =CHOOSE(Control!$C$8,'S&M Build'!H13,'S&M Build'!H20,'S&M Build'!H27) -> 13 | I27: =CHOOSE(Control!$C$8,'S&M Build'!I13,'S&M Build'!I20,'S&M Build'!I27) -> 16
B28: VP Sales | C28: =CHOOSE(Control!$C$8,'S&M Build'!C14,'S&M Build'!C21,'S&M Build'!C28) -> 0 | D28: =CHOOSE(Control!$C$8,'S&M Build'!D14,'S&M Build'!D21,'S&M Build'!D28) -> 0 | E28: =CHOOSE(Control!$C$8,'S&M Build'!E14,'S&M Build'!E21,'S&M Build'!E28) -> 0 | F28: =CHOOSE(Control!$C$8,'S&M Build'!F14,'S&M Build'!F21,'S&M Build'!F28) -> 1 | G28: =CHOOSE(Control!$C$8,'S&M Build'!G14,'S&M Build'!G21,'S&M Build'!G28) -> 1 | H28: =CHOOSE(Control!$C$8,'S&M Build'!H14,'S&M Build'!H21,'S&M Build'!H28) -> 1 | I28: =CHOOSE(Control!$C$8,'S&M Build'!I14,'S&M Build'!I21,'S&M Build'!I28) -> 1
B29: New-client capacity (founder + reps x quota) | C29: =C25+C26*$C$18+C27*$C$19+C28*$C$20 -> 10 | D29: =D25+D26*$C$18+D27*$C$19+D28*$C$20 -> 23 | E29: =E25+E26*$C$18+E27*$C$19+E28*$C$20 -> 36 | F29: =F25+F26*$C$18+F27*$C$19+F28*$C$20 -> 142 | G29: =G25+G26*$C$18+G27*$C$19+G28*$C$20 -> 221 | H29: =H25+H26*$C$18+H27*$C$19+H28*$C$20 -> 280 | I29: =I25+I26*$C$18+I27*$C$19+I28*$C$20 -> 325
B31: CLIENT ROLL-FORWARD & BOTTOM-UP REVENUE
B32: Applicable retention rate | C32: =$C$21 -> 1 | D32: =$C$21 -> 1 | E32: =$C$21 -> 1 | F32: =$C$22 -> 0.9 | G32: =$C$22 -> 0.9 | H32: =$C$22 -> 0.9 | I32: =$C$22 -> 0.9
B33: Beginning clients | C33: 0 | D33: =C37 -> 10 | E33: =D37 -> 33 | F33: =E37 -> 69 | G33: =F37 -> 204.1 | H33: =G37 -> 404.69 | I33: =H37 -> 644.221
B34: Retained clients (beginning x retention) | C34: =C33*C32 -> 0 | D34: =D33*D32 -> 10 | E34: =E33*E32 -> 33 | F34: =F33*F32 -> 62.1 | G34: =G33*G32 -> 183.69 | H34: =H33*H32 -> 364.221 | I34: =I33*I32 -> 579.7989
B35: New clients this year (= capacity, row 29) | C35: =C29 -> 10 | D35: =D29 -> 23 | E35: =E29 -> 36 | F35: =F29 -> 142 | G35: =G29 -> 221 | H35: =H29 -> 280 | I35: =I29 -> 325
B36: of which: Jan-Mar / Jul-Aug | C36: =TEXT(C35*$C$14,"0.0")&" / "&TEXT(C35*$C$15,"0.0") -> 5.5 / 4.5 | D36: =TEXT(D35*$C$14,"0.0")&" / "&TEXT(D35*$C$15,"0.0") -> 12.7 / 10.4 | E36: =TEXT(E35*$C$14,"0.0")&" / "&TEXT(E35*$C$15,"0.0") -> 19.8 / 16.2 | F36: =TEXT(F35*$C$14,"0.0")&" / "&TEXT(F35*$C$15,"0.0") -> 78.1 / 63.9 | G36: =TEXT(G35*$C$14,"0.0")&" / "&TEXT(G35*$C$15,"0.0") -> 121.6 / 99.5 | H36: =TEXT(H35*$C$14,"0.0")&" / "&TEXT(H35*$C$15,"0.0") -> 154.0 / 126.0 | I36: =TEXT(I35*$C$14,"0.0")&" / "&TEXT(I35*$C$15,"0.0") -> 178.8 / 146.3
B37: Ending clients | C37: =C34+C35 -> 10 | D37: =D34+D35 -> 33 | E37: =E34+E35 -> 69 | F37: =F34+F35 -> 204.1 | G37: =G34+G35 -> 404.69 | H37: =H34+H35 -> 644.221 | I37: =I34+I35 -> 904.7989
B39: Revenue — retained clients (full year, at mid rate) | C39: =C34*$C$10 -> 0 | D39: =D34*$C$10 -> 540000 | E39: =E34*$C$10 -> 1782000 | F39: =F34*$C$10 -> 3353400 | G39: =G34*$C$10 -> 9919260 | H39: =H34*$C$10 -> 19667934 | I39: =I34*$C$10 -> 31309141
B40: Revenue — new clients (blended months x mid rate) | C40: =C35*$C$8*$C$16 -> 348750 | D40: =D35*$C$8*$C$16 -> 802125 | E40: =E35*$C$8*$C$16 -> 1255500 | F40: =F35*$C$8*$C$16 -> 4952250 | G40: =G35*$C$8*$C$16 -> 7707375 | H40: =H35*$C$8*$C$16 -> 9765000 | I40: =I35*$C$8*$C$16 -> 11334375
B41: BOTTOM-UP REVENUE | C41: =C39+C40 -> 348750 | D41: =D39+D40 -> 1342125 | E41: =E39+E40 -> 3037500 | F41: =F39+F40 -> 8305650 | G41: =G39+G40 -> 17626635 | H41: =H39+H40 -> 29432934 | I41: =I39+I40 -> 42643516
B43: PRESSURE TEST · bottom-up vs. currently modeled (active scenario)
B44: Bottom-up revenue | C44: =C41 -> 348750 | D44: =D41 -> 1342125 | E44: =E41 -> 3037500 | F44: =F41 -> 8305650 | G44: =G41 -> 17626635 | H44: =H41 -> 29432934 | I44: =I41 -> 42643516
B45: Currently modeled (Scenarios tab, active scenario) | C45: =INDEX(Scenarios!$C$6:$I$8,Control!$C$8,1) -> 348750 | D45: =INDEX(Scenarios!$C$6:$I$8,Control!$C$8,2) -> 1342125 | E45: =INDEX(Scenarios!$C$6:$I$8,Control!$C$8,3) -> 3177500 | F45: =INDEX(Scenarios!$C$6:$I$8,Control!$C$8,4) -> 10188875 | G45: =INDEX(Scenarios!$C$6:$I$8,Control!$C$8,5) -> 23192222 | H45: =INDEX(Scenarios!$C$6:$I$8,Control!$C$8,6) -> 40601094 | I45: =INDEX(Scenarios!$C$6:$I$8,Control!$C$8,7) -> 60581809
B46: Gap | C46: =C44-C45 -> 0 | D46: =D44-D45 -> 0 | E46: =E44-E45 -> -140000 | F46: =F44-F45 -> -1883225 | G46: =G44-G45 -> -5565587.5 | H46: =H44-H45 -> -11168160 | I46: =I44-I45 -> -17938293
B47: Gap, % | C47: =C46/C45 -> 0 | D47: =D46/D45 -> 0 | E47: =E46/E45 -> -0.044059795 | F47: =F46/F45 -> -0.1848315 | G47: =G46/G45 -> -0.23997646 | H47: =H46/H45 -> -0.27507042 | I47: =I46/I45 -> -0.29610033
B49: WHAT IT WOULD TAKE TO HIT EACH MILESTONE · assumes prior years also hit target
...

Sheet Staffing Plan
B1: Staffing Plan — active scenario
B2: Consolidated across S&M, Product & Data Eng, and G&A. Follows the Control toggle — flip Bear/Base/Bull and this view updates.
C4: Year 1 | D4: Year 2 | E4: Year 3 | F4: Year 4 | G4: Year 5 | H4: Year 6 | I4: Year 7
B5: G&A / LEADERSHIP
B6: Founder / CEO (headcount) | C6: 1 | D6: 1 | E6: 1 | F6: 1 | G6: 1 | H6: 1 | I6: 1
B7: cost | C7: =CHOOSE(Control!$C$8,'G&A & Exec Comp Build'!C6,'G&A & Exec Comp Build'!C7,'G&A & Exec Comp Build'!C8) -> 250000 | D7: =CHOOSE(Control!$C$8,'G&A & Exec Comp Build'!D6,'G&A & Exec Comp Build'!D7,'G&A & Exec Comp Build'!D8) -> 275000 | E7: =CHOOSE(Control!$C$8,'G&A & Exec Comp Build'!E6,'G&A & Exec Comp Build'!E7,'G&A & Exec Comp Build'!E8) -> 300000 | F7: =CHOOSE(Control!$C$8,'G&A & Exec Comp Build'!F6,'G&A & Exec Comp Build'!F7,'G&A & Exec Comp Build'!F8) -> 300000 | G7: =CHOOSE(Control!$C$8,'G&A & Exec Comp Build'!G6,'G&A & Exec Comp Build'!G7,'G&A & Exec Comp Build'!G8) -> 300000 | H7: =CHOOSE(Control!$C$8,'G&A & Exec Comp Build'!H6,'G&A & Exec Comp Build'!H7,'G&A & Exec Comp Build'!H8) -> 300000 | I7: =CHOOSE(Control!$C$8,'G&A & Exec Comp Build'!I6,'G&A & Exec Comp Build'!I7,'G&A & Exec Comp Build'!I8) -> 300000
B8: Executive Assistant (headcount) | C8: 1 | D8: 1 | E8: 1 | F8: 1 | G8: 1 | H8: 1 | I8: 1
B9: cost | C9: ='G&A & Exec Comp Build'!C29 -> 65000 | D9: ='G&A & Exec Comp Build'!D29 -> 70000 | E9: ='G&A & Exec Comp Build'!E29 -> 73000 | F9: ='G&A & Exec Comp Build'!F29 -> 76000 | G9: ='G&A & Exec Comp Build'!G29 -> 80000 | H9: ='G&A & Exec Comp Build'!H29 -> 84000 | I9: ='G&A & Exec Comp Build'!I29 -> 88000
B10: CFO / Head of Finance (headcount, Base/Bull only, from Y5) | C10: =IF(AND(Control!$C$8>1,'G&A & Exec Comp Build'!C15+'G&A & Exec Comp Build'!C16>0),1,0) -> 0 | D10: =IF(AND(Control!$C$8>1,'G&A & Exec Comp Build'!D15+'G&A & Exec Comp Build'!D16>0),1,0) -> 0 | E10: =IF(AND(Control!$C$8>1,'G&A & Exec Comp Build'!E15+'G&A & Exec Comp Build'!E16>0),1,0) -> 0 | F10: =IF(AND(Control!$C$8>1,'G&A & Exec Comp Build'!F15+'G&A & Exec Comp Build'!F16>0),1,0) -> 0 | G10: =IF(AND(Control!$C$8>1,'G&A & Exec Comp Build'!G15+'G&A & Exec Comp Build'!G16>0),1,0) -> 1 | H10: =IF(AND(Control!$C$8>1,'G&A & Exec Comp Build'!H15+'G&A & Exec Comp Build'!H16>0),1,0) -> 1 | I10: =IF(AND(Control!$C$8>1,'G&A & Exec Comp Build'!I15+'G&A & Exec Comp Build'!I16>0),1,0) -> 1
B11: cost | C11: =IF(Control!$C$8=3,'G&A & Exec Comp Build'!C16,'G&A & Exec Comp Build'!C15) -> 0 | D11: =IF(Control!$C$8=3,'G&A & Exec Comp Build'!D16,'G&A & Exec Comp Build'!D15) -> 0 | E11: =IF(Control!$C$8=3,'G&A & Exec Comp Build'!E16,'G&A & Exec Comp Build'!E15) -> 0 | F11: =IF(Control!$C$8=3,'G&A & Exec Comp Build'!F16,'G&A & Exec Comp Build'!F15) -> 0 | G11: =IF(Control!$C$8=3,'G&A & Exec Comp Build'!G16,'G&A & Exec Comp Build'!G15) -> 230000 | H11: =IF(Control!$C$8=3,'G&A & Exec Comp Build'!H16,'G&A & Exec Comp Build'!H15) -> 245000 | I11: =IF(Control!$C$8=3,'G&A & Exec Comp Build'!I16,'G&A & Exec Comp Build'!I15) -> 260000
B12: Delivery analysts (COGS) | C12: ='COGS & Overhead Build'!C57 -> 0 | D12: ='COGS & Overhead Build'!D57 -> 0 | E12: ='COGS & Overhead Build'!E57 -> 6 | F12: ='COGS & Overhead Build'!F57 -> 15 | G12: ='COGS & Overhead Build'!G57 -> 26 | H12: ='COGS & Overhead Build'!H57 -> 36 | I12: ='COGS & Overhead Build'!I57 -> 46
B13: SALES & MARKETING
B14: BD / channel reps | C14: =CHOOSE(Control!$C$8,'S&M Build'!C12,'S&M Build'!C19,'S&M Build'!C26) -> 0 | D14: =CHOOSE(Control!$C$8,'S&M Build'!D12,'S&M Build'!D19,'S&M Build'!D26) -> 1 | E14: =CHOOSE(Control!$C$8,'S&M Build'!E12,'S&M Build'!E19,'S&M Build'!E26) -> 2 | F14: =CHOOSE(Control!$C$8,'S&M Build'!F12,'S&M Build'!F19,'S&M Build'!F26) -> 7 | G14: =CHOOSE(Control!$C$8,'S&M Build'!G12,'S&M Build'!G19,'S&M Build'!G26) -> 11 | H14: =CHOOSE(Control!$C$8,'S&M Build'!H12,'S&M Build'!H19,'S&M Build'!H26) -> 14 | I14: =CHOOSE(Control!$C$8,'S&M Build'!I12,'S&M Build'!I19,'S&M Build'!I26) -> 16
B15: Enterprise sales reps | C15: =CHOOSE(Control!$C$8,'S&M Build'!C13,'S&M Build'!C20,'S&M Build'!C27) -> 0 | D15: =CHOOSE(Control!$C$8,'S&M Build'!D13,'S&M Build'!D20,'S&M Build'!D27) -> 0 | E15: =CHOOSE(Control!$C$8,'S&M Build'!E13,'S&M Build'!E20,'S&M Build'!E27) -> 0 | F15: =CHOOSE(Control!$C$8,'S&M Build'!F13,'S&M Build'!F20,'S&M Build'!F27) -> 6 | G15: =CHOOSE(Control!$C$8,'S&M Build'!G13,'S&M Build'!G20,'S&M Build'!G27) -> 10 | H15: =CHOOSE(Control!$C$8,'S&M Build'!H13,'S&M Build'!H20,'S&M Build'!H27) -> 13 | I15: =CHOOSE(Control!$C$8,'S&M Build'!I13,'S&M Build'!I20,'S&M Build'!I27) -> 16
B16: VP Sales / Growth | C16: =CHOOSE(Control!$C$8,'S&M Build'!C14,'S&M Build'!C21,'S&M Build'!C28) -> 0 | D16: =CHOOSE(Control!$C$8,'S&M Build'!D14,'S&M Build'!D21,'S&M Build'!D28) -> 0 | E16: =CHOOSE(Control!$C$8,'S&M Build'!E14,'S&M Build'!E21,'S&M Build'!E28) -> 0 | F16: =CHOOSE(Control!$C$8,'S&M Build'!F14,'S&M Build'!F21,'S&M Build'!F28) -> 1 | G16: =CHOOSE(Control!$C$8,'S&M Build'!G14,'S&M Build'!G21,'S&M Build'!G28) -> 1 | H16: =CHOOSE(Control!$C$8,'S&M Build'!H14,'S&M Build'!H21,'S&M Build'!H28) -> 1 | I16: =CHOOSE(Control!$C$8,'S&M Build'!I14,'S&M Build'!I21,'S&M Build'!I28) -> 1
B17: S&M headcount cost (excl. marketing program $) | C17: =C14*'S&M Build'!$C$5+C15*'S&M Build'!$C$6+C16*'S&M Build'!$C$7 -> 0 | D17: =D14*'S&M Build'!$C$5+D15*'S&M Build'!$C$6+D16*'S&M Build'!$C$7 -> 150000 | E17: =E14*'S&M Build'!$C$5+E15*'S&M Build'!$C$6+E16*'S&M Build'!$C$7 -> 300000 | F17: =F14*'S&M Build'!$C$5+F15*'S&M Build'!$C$6+F16*'S&M Build'!$C$7 -> 2420000 | G17: =G14*'S&M Build'!$C$5+G15*'S&M Build'!$C$6+G16*'S&M Build'!$C$7 -> 3760000 | H17: =H14*'S&M Build'!$C$5+H15*'S&M Build'!$C$6+H16*'S&M Build'!$C$7 -> 4765000 | I17: =I14*'S&M Build'!$C$5+I15*'S&M Build'!$C$6+I16*'S&M Build'!$C$7 -> 5620000
B18: CS analysts (COGS) | C18: ='COGS & Overhead Build'!C60 -> 0 | D18: ='COGS & Overhead Build'!D60 -> 1 | E18: ='COGS & Overhead Build'!E60 -> 2 | F18: ='COGS & Overhead Build'!F60 -> 3 | G18: ='COGS & Overhead Build'!G60 -> 6 | H18: ='COGS & Overhead Build'!H60 -> 8 | I18: ='COGS & Overhead Build'!I60 -> 10
B19: PRODUCT & DATA ENGINEERING
B20: Engineers / data scientists | C20: =CHOOSE(Control!$C$8,'Product & Data Eng Build'!C12,'Product & Data Eng Build'!C18,'Product & Data Eng Build'!C24) -> 0 | D20: =CHOOSE(Control!$C$8,'Product & Data Eng Build'!D12,'Product & Data Eng Build'!D18,'Product & Data Eng Build'!D24) -> 1 | E20: =CHOOSE(Control!$C$8,'Product & Data Eng Build'!E12,'Product & Data Eng Build'!E18,'Product & Data Eng Build'!E24) -> 2 | F20: =CHOOSE(Control!$C$8,'Product & Data Eng Build'!F12,'Product & Data Eng Build'!F18,'Product & Data Eng Build'!F24) -> 5 | G20: =CHOOSE(Control!$C$8,'Product & Data Eng Build'!G12,'Product & Data Eng Build'!G18,'Product & Data Eng Build'!G24) -> 10 | H20: =CHOOSE(Control!$C$8,'Product & Data Eng Build'!H12,'Product & Data Eng Build'!H18,'Product & Data Eng Build'!H24) -> 14 | I20: =CHOOSE(Control!$C$8,'Product & Data Eng Build'!I12,'Product & Data Eng Build'!I18,'Product & Data Eng Build'!I24) -> 18
B21: Head of Product / CTO | C21: =CHOOSE(Control!$C$8,'Product & Data Eng Build'!C13,'Product & Data Eng Build'!C19,'Product & Data Eng Build'!C25) -> 0 | D21: =CHOOSE(Control!$C$8,'Product & Data Eng Build'!D13,'Product & Data Eng Build'!D19,'Product & Data Eng Build'!D25) -> 0 | E21: =CHOOSE(Control!$C$8,'Product & Data Eng Build'!E13,'Product & Data Eng Build'!E19,'Product & Data Eng Build'!E25) -> 0 | F21: =CHOOSE(Control!$C$8,'Product & Data Eng Build'!F13,'Product & Data Eng Build'!F19,'Product & Data Eng Build'!F25) -> 1 | G21: =CHOOSE(Control!$C$8,'Product & Data Eng Build'!G13,'Product & Data Eng Build'!G19,'Product & Data Eng Build'!G25) -> 1 | H21: =CHOOSE(Control!$C$8,'Product & Data Eng Build'!H13,'Product & Data Eng Build'!H19,'Product & Data Eng Build'!H25) -> 1 | I21: =CHOOSE(Control!$C$8,'Product & Data Eng Build'!I13,'Product & Data Eng Build'!I19,'Product & Data Eng Build'!I25) -> 1
B22: Product/Eng headcount cost | C22: =C20*'Product & Data Eng Build'!$C$5+C21*'Product & Data Eng Build'!$C$7 -> 0 | D22: =D20*'Product & Data Eng Build'!$C$5+D21*'Product & Data Eng Build'!$C$7 -> 165000 | E22: =E20*'Product & Data Eng Build'!$C$5+E21*'Product & Data Eng Build'!$C$7 -> 330000 | F22: =F20*'Product & Data Eng Build'!$C$5+F21*'Product & Data Eng Build'!$C$7 -> 1055000 | G22: =G20*'Product & Data Eng Build'!$C$5+G21*'Product & Data Eng Build'!$C$7 -> 1880000 | H22: =H20*'Product & Data Eng Build'!$C$5+H21*'Product & Data Eng Build'!$C$7 -> 2540000 | I22: =I20*'Product & Data Eng Build'!$C$5+I21*'Product & Data Eng Build'!$C$7 -> 3200000
